Workbook

Sheet _README
A1: Master Dataset ของโครงงาน NutriPlan (งานที่ 4 DADD)
A3: โครงสร้าง: 12 ชีตข้อมูล ชื่อชีตตรงกับชื่อ Node ใน Firebase และชื่อคอลัมน์ตรงกับพจนานุกรมข้อมูลในรายงานหัวข้อ 3
A4: ข้อมูลอ้างอิง (Lookup): categories, vendor_types, activity_levels, health_goals, nutrient_limits
A5: ข้อมูลหลัก (Master): menus, articles, menu_images, sources, users
A6: ข้อมูลธุรกรรม (Transaction): user_targets, meal_logs
A7: ชีต _summary คำนวณตัวชี้วัดด้วยสูตร จึงอัปเดตอัตโนมัติเมื่อแก้ไขข้อมูล
A8: ชีต user_targets เป็นสูตรทั้งหมด (ยกเว้น calculated_at) คำนวณจากชีต users
A10: หลักการบันทึกข้อมูล
A11: • รหัสข้อมูลตัวพิมพ์เล็ก ใช้เป็นคีย์ JSON ได้ทันที (ไม่มี . $ # [ ] /)
A12: • ข้อมูลหลายค่าในเซลล์เดียว (tags, source_ids) คั่นด้วย | ส่วน key_points คั่นด้วย " | "
A13: • วันที่ใช้ ISO 8601 (YYYY-MM-DD) ยกเว้น birth_year เป็นปี พ.ศ.
A14: • คอลัมน์ที่มีค่ามาตรฐานตั้ง Data Validation ไว้ เช่น category_id, verification_status, meal_type, role
... A25: • ค่าโภชนาการ = ค่า Thai FCD ต่อ 100 ก. × serving_g หรือผลรวมจากสูตรอาหาร สารอาหารที่ Thai FCD ไม่รายงาน (ส่วนใหญ่คือน้ำตาล) ยังเป็นค่าประมาณเดิม ระบุในคอลัมน์ fields_retained_from_estimate

Sheet _summary
A1: ตัวชี้วัด | B1: ค่า | C1: สูตร/หมายเหตุ
A2: จำนวนแถว categories | B2: =COUNTA(categories!A:A)-1 | C2: COUNTA ของคอลัมน์รหัส
A3: จำนวนแถว vendor_types | B3: =COUNTA(vendor_types!A:A)-1 | C3: COUNTA ของคอลัมน์รหัส
A4: จำนวนแถว activity_levels | B4: =COUNTA(activity_levels!A:A)-1 | C4: COUNTA ของคอลัมน์รหัส
A5: จำนวนแถว health_goals | B5: =COUNTA(health_goals!A:A)-1 | C5: COUNTA ของคอลัมน์รหัส
A6: จำนวนแถว nutrient_limits | B6: =COUNTA(nutrient_limits!A:A)-1 | C6: COUNTA ของคอลัมน์รหัส
A7: จำนวนแถว menus | B7: =COUNTA(menus!A:A)-1 | C7: COUNTA ของคอลัมน์รหัส
A8: จำนวนแถว articles | B8: =COUNTA(articles!A:A)-1 | C8: COUNTA ของคอลัมน์รหัส
A9: จำนวนแถว menu_images | B9: =COUNTA(menu_images!A:A)-1 | C9: COUNTA ของคอลัมน์รหัส
A10: จำนวนแถว sources | B10: =COUNTA(sources!A:A)-1 | C10: COUNTA ของคอลัมน์รหัส
A11: จำนวนแถว users | B11: =COUNTA(users!A:A)-1 | C11: COUNTA ของคอลัมน์รหัส
A12: จำนวนแถว user_targets | B12: =COUNTA(user_targets!A:A)-1 | C12: COUNTA ของคอลัมน์รหัส
A13: จำนวนแถว meal_logs | B13: =COUNTA(meal_logs!A:A)-1 | C13: COUNTA ของคอลัมน์รหัส
A14: รวมทุกชีต | B14: =SUM(B2:B13)
A15: เมนูที่ยัง PENDING | B15: =COUNTIF(menus!V:V,"PENDING")
A16: ภาพเมนูสถานะ DONE | B16: =COUNTIFS(menu_images!C:C,"menu",menu_images!H:H,"DONE")
A17: ภาพปกบทความสถานะ TODO | B17: =COUNTIFS(menu_images!C:C,"article_cover",menu_images!H:H,"TODO")
A18: จำนวนวัน-ผู้ใช้ที่มีการบันทึก (ดูชีต meal_logs) | B18: =SUMPRODUCT((meal_logs!B2:B1109&meal_logs!C2:C1109<>"")/COUNTIFS(meal_logs!B2:B1109,meal_logs!B2:B1109,meal_logs!C2:C1109,meal_logs!C2:C1109)) | C18: คู่ user_id + log_date ที่ไม่ซ้ำ
A20: หมวดอาหาร | B20: จำนวนเมนู | C20: พลังงานเฉลี่ย (kcal) | D20: โซเดียมเฉลี่ย (มก.)
A21: =categories!A2 | B21: =COUNTIF(menus!$D$2:$D$50,A21) | C21: =ROUND(AVERAGEIF(menus!$D$2:$D$50,A21,menus!$I$2:$I$50),0) | D21: =ROUND(AVERAGEIF(menus!$D$2:$D$50,A21,menus!$O$2:$O$50),0)
A22: =categories!A3 | B22: =COUNTIF(menus!$D$2:$D$50,A22) | C22: =ROUND(AVERAGEIF(menus!$D$2:$D$50,A22,menus!$I$2:$I$50),0) | D22: =ROUND(AVERAGEIF(menus!$D$2:$D$50,A22,menus!$O$2:$O$50),0)
A23: =categories!A4 | B23: =COUNTIF(menus!$D$2:$D$50,A23) | C23: =ROUND(AVERAGEIF(menus!$D$2:$D$50,A23,menus!$I$2:$I$50),0) | D23: =ROUND(AVERAGEIF(menus!$D$2:$D$50,A23,menus!$O$2:$O$50),0)
A24: =categories!A5 | B24: =COUNTIF(menus!$D$2:$D$50,A24) | C24: =ROUND(AVERAGEIF(menus!$D$2:$D$50,A24,menus!$I$2:$I$50),0) | D24: =ROUND(AVERAGEIF(menus!$D$2:$D$50,A24,menus!$O$2:$O$50),0)
A25: =categories!A6 | B25: =COUNTIF(menus!$D$2:$D$50,A25) | C25: =ROUND(AVERAGEIF(menus!$D$2:$D$50,A25,menus!$I$2:$I$50),0) | D25: =ROUND(AVERAGEIF(menus!$D$2:$D$50,A25,menus!$O$2:$O$50),0)
A26: =categories!A7 | B26: =COUNTIF(menus!$D$2:$D$50,A26) | C26: =ROUND(AVERAGEIF(menus!$D$2:$D$50,A26,menus!$I$2:$I$50),0) | D26: =ROUND(AVERAGEIF(menus!$D$2:$D$50,A26,menus!$O$2:$O$50),0)
A27: =categories!A8 | B27: =COUNTIF(menus!$D$2:$D$50,A27) | C27: =ROUND(AVERAGEIF(menus!$D$2:$D$50,A27,menus!$I$2:$I$50),0) | D27: =ROUND(AVERAGEIF(menus!$D$2:$D$50,A27,menus!$O$2:$O$50),0)
A28: =categories!A9 | B28: =COUNTIF(menus!$D$2:$D$50,A28) | C28: =ROUND(AVERAGEIF(menus!$D$2:$D$50,A28,menus!$I$2:$I$50),0) | D28: =ROUND(AVERAGEIF(menus!$D$2:$D$50,A28,menus!$O$2:$O$50),0)
A29: รวม / เฉลี่ยทั้งหมด | B29: =SUM(B21:B28) | C29: =ROUND(AVERAGE(menus!I2:I50),0) | D29: =ROUND(AVERAGE(menus!O2:O50),0)

Sheet categories
A1: category_id | B1: name_th | C1: name_en | D1: description | E1: icon_file | F1: color_hex | G1: sort_order
A2: cat_rice | B2: ข้าวจานเดียว | C2: Rice Dishes | D2: ข้าวราดหน้าหรือข้าวพร้อมกับข้าวในจานเดียว | E2: icon_cat_rice.svg | F2: #C2410C | G2: 1
A3: cat_stir | B3: ข้าวผัด/ตามสั่ง | C3: Stir-fried Dishes | D3: อาหารผัดสั่งทำสดราดข้าว | E3: icon_cat_stir.svg | F3: #B45309 | G3: 2
A4: cat_noodle | B4: ก๋วยเตี๋ยวและเส้น | C4: Noodle Dishes | D4: อาหารประเภทเส้นทั้งน้ำและแห้ง | E4: icon_cat_noodle.svg | F4: #0F766E | G4: 3
A5: cat_isaan | B5: อาหารอีสาน | C5: Isan Food | D5: ส้มตำ ลาบ ย่าง และอาหารอีสานทั่วไป | E5: icon_cat_isaan.svg | F5: #15803D | G5: 4
A6: cat_curry | B6: แกงและกับข้าว | C6: Curry and Side Dish | D6: แกง ต้ม ผัดผัก ที่สั่งเป็นกับข้าว | E6: icon_cat_curry.svg | F6: #A16207 | G6: 5
A7: cat_drink | B7: เครื่องดื่ม | C7: Beverages | D7: เครื่องดื่มที่สั่งคู่กับมื้ออาหาร | E7: icon_cat_drink.svg | F7: #1D4ED8 | G7: 6
A8: cat_dessert | B8: ของหวานและผลไม้ | C8: Dessert and Fruit | D8: ของหวานและผลไม้ที่รับประทานหลังมื้ออาหาร | E8: icon_cat_dessert.svg | F8: #BE185D | G8: 7
A9: cat_side | B9: ข้าวและเครื่องเคียง | C9: Staple and Side | D9: ข้าวสวย ข้าวเหนียว และเครื่องเคียงแยกจาน | E9: icon_cat_side.svg | F9: #4D7C0F | G9: 8

Sheet vendor_types
A1: vendor_type_id | B1: name_th | C1: name_en
A2: shop_tamsang | B2: ร้านอาหารตามสั่ง | C2: Made-to-order Shop
A3: shop_rice | B3: ร้านข้าวจานเดียว | C3: Single-dish Rice Shop
A4: shop_noodle | B4: ร้านก๋วยเตี๋ยว | C4: Noodle Shop
A5: shop_isaan | B5: ร้านส้มตำ/อาหารอีสาน | C5: Isan Food Shop
A6: shop_curry | B6: ร้านข้าวราดแกง | C6: Curry-over-rice Shop
A7: shop_drink | B7: ร้านเครื่องดื่ม | C7: Beverage Stall
A8: shop_dessert | B8: ร้านของหวาน/ผลไม้ | C8: Dessert and Fruit Stall

Sheet activity_levels
A1: activity_id | B1: name_th | C1: pal_factor | D1: example | E1: sort_order
A2: act_sedentary | B2: นั่งทำงานเป็นหลัก ไม่ออกกำลังกาย | C2: 1.2 | D2: นั่งเรียนหรือนั่งทำงานเกือบทั้งวัน | E2: 1
A3: act_light | B3: ออกกำลังกายเบา 1-3 วันต่อสัปดาห์ | C3: 1.375 | D3: เดินระหว่างตึกเรียน ออกกำลังกายเบาบ้าง | E3: 2
A4: act_moderate | B4: ออกกำลังกายปานกลาง 3-5 วันต่อสัปดาห์ | C4: 1.55 | D4: ออกกำลังกายสม่ำเสมอหรือทำงานที่ต้องยืนเดิน | E4: 3
A5: act_active | B5: ออกกำลังกายหนัก 6-7 วันต่อสัปดาห์ | C5: 1.725 | D5: เล่นกีฬาหรือเข้ายิมเกือบทุกวัน | E5: 4
A6: act_very | B6: ออกกำลังกายหนักมากหรือใช้แรงงาน | C6: 1.9 | D6: นักกีฬาหรือผู้ใช้แรงงานหนัก | E6: 5

Sheet health_goals
A1: goal_id | B1: name_th | C1: kcal_adjust | D1: description | E1: sort_order
A2: goal_lose | B2: ลดน้ำหนัก | C2: -500 | D2: ลดพลังงานจาก TDEE วันละ 500 กิโลแคลอรี | E2: 1
A3: goal_maintain | B3: คงน้ำหนัก | C3: 0 | D3: รับพลังงานเท่ากับ TDEE | E3: 2
A4: goal_gain | B4: เพิ่มน้ำหนัก | C4: 300 | D4: เพิ่มพลังงานจาก TDEE วันละ 300 กิโลแคลอรี | E4: 3

Sheet nutrient_limits
A1: nutrient_key | B1: name_th | C1: name_en | D1: unit | E1: limit_type | F1: limit_value | G1: source_id | H1: article_id | I1: sort_order
A2: energy_kcal | B2: พลังงาน | C2: Energy | D2: kcal | E2: personal | F2: 0 | G2: src_05 | H2: article_01 | I2: 1
A3: protein_g | B3: โปรตีน | C3: Protein | D3: g | E3: per_kg | F3: 1 | G3: src_02 | H3: article_05 | I3: 2
A4: fat_g | B4: ไขมัน | C4: Fat | D4: g | E4: info | F4: 0 | G4: src_02 | H4: article_09 | I4: 3
A5: carb_g | B5: คาร์โบไฮเดรต | C5: Carbohydrate | D5: g | E5: info | F5: 0 | G5: src_02 | H5: article_07 | I5: 4
A6: sugar_g | B6: น้ำตาล | C6: Sugar | D6: g | E6: max | F6: 50 | G6: src_04 | H6: article_04 | I6: 5
A7: fiber_g | B7: ใยอาหาร | C7: Dietary Fiber | D7: g | E7: min | F7: 25 | G7: src_02 | H7: article_06 | I7: 6
A8: sodium_mg | B8: โซเดียม | C8: Sodium | D8: mg | E8: max | F8: 2000 | G8: src_03 | H8: article_03 | I8: 7

Sheet menus
A1: menu_id | B1: name_th | C1: name_en | D1: category_id | E1: vendor_type_id | F1: serving_desc | G1: serving_g | H1: price_thb | I1: energy_kcal | J1: protein_g | K1: fat_g | L1: carb_g | M1: sugar_g | N1: fiber_g | O1: sodium_mg | P1: is_vegetarian | Q1: spicy_level | R1: tags | S1: image_thumb | T1: image_detail | U1: source_id | V1: verification_status | W1: updated_at
A2: menu_001 | B2: ข้าวมันไก่ | C2: Hainanese Chicken Rice | D2: cat_rice | E2: shop_rice | F2: 1 จาน | G2: 350 | H2: 50 | I2: 693 | J2: 23.6 | K2: 32.4 | L2: 74.4 | M2: 3 | N2: 5.2 | O2: 1100 | P2: =FALSE() | Q2: 0 | R2: ไก่|ข้าว|มื้อกลางวัน | S2: images/menus/menu_001_thumb.webp | T2: images/menus/menu_001_detail.webp | U2: src_01 | V2: VERIFIED | W2: 2026-10-19
A3: menu_002 | B3: ข้าวหมูแดง | C3: Red Pork with Rice | D3: cat_rice | E3: shop_rice | F3: 1 จาน | G3: 330 | H3: 50 | I3: 508 | J3: 20.8 | K3: 13.8 | L3: 75 | M3: 12 | N3: 0.7 | O3: 937 | P3: =FALSE() | Q3: 0 | R3: หมู|ข้าว | S3: images/menus/menu_002_thumb.webp | T3: images/menus/menu_002_detail.webp | U3: src_01 | V3: VERIFIED | W3: 2026-10-19
A4: menu_003 | B4: ข้าวขาหมู | C4: Stewed Pork Leg with Rice | D4: cat_rice | E4: shop_rice | F4: 1 จาน | G4: 380 | H4: 55 | I4: 612 | J4: 27.3 | K4: 22.5 | L4: 73.5 | M4: 8 | N4: 3.8 | O4: 1231 | P4: =FALSE() | Q4: 0 | R4: หมู|ข้าว|ไขมันสูง | S4: images/menus/menu_003_thumb.webp | T4: images/menus/menu_003_detail.webp | U4: src_01 | V4: VERIFIED | W4: 2026-10-19
A5: menu_004 | B5: ข้าวหน้าเป็ด | C5: Roasted Duck with Rice | D5: cat_rice | E5: shop_rice | F5: 1 จาน | G5: 350 | H5: 60 | I5: 452 | J5: 18.2 | K5: 14.7 | L5: 58.5 | M5: 6 | N5: 6.7 | O5: 1120 | P5: =FALSE() | Q5: 0 | R5: เป็ด|ข้าว|โปรตีนสูง | S5: images/menus/menu_004_thumb.webp | T5: images/menus/menu_004_detail.webp | U5: src_01 | V5: VERIFIED | W5: 2026-10-19
A6: menu_005 | B6: ข้าวคลุกกะปิ | C6: Shrimp Paste Fried Rice | D6: cat_rice | E6: shop_tamsang | F6: 1 จาน | G6: 320 | H6: 50 | I6: 546 | J6: 25.5 | K6: 16.3 | L6: 73.8 | M6: 9 | N6: 1.3 | O6: 1090 | P6: =FALSE() | Q6: 1 | R6: กุ้ง|ข้าว|โซเดียมสูง | S6: images/menus/menu_005_thumb.webp | T6: images/menus/menu_005_detail.webp | U6: src_01 | V6: VERIFIED | W6: 2026-10-19
A7: menu_006 | B7: ข้าวหมูกรอบ | C7: Crispy Pork with Rice | D7: cat_rice | E7: shop_rice | F7: 1 จาน | G7: 330 | H7: 55 | I7: 708 | J7: 21 | K7: 38 | L7: 70.5 | M7: 8 | N7: 0.1 | O7: 700 | P7: =FALSE() | Q7: 0 | R7: หมู|ข้าว|ไขมันสูง | S7: images/menus/menu_006_thumb.webp | T7: images/menus/menu_006_detail.webp | U7: src_01 | V7: VERIFIED | W7: 2026-10-19
A8: menu_007 | B8: ข้าวผัดกะเพราหมูสับไข่ดาว | C8: Stir-fried Basil Pork with Rice and Fried Egg | D8: cat_stir | E8: shop_tamsang | F8: 1 จาน | G8: 380 | H8: 55 | I8: 857 | J8: 40 | K8: 46 | L8: 70.5 | M8: 3.2 | N8: 0.4 | O8: 1445 | P8: =FALSE() | Q8: 2 | R8: หมู|ไข่|เผ็ด|โซเดียมสูง | S8: images/menus/menu_007_thumb.webp | T8: images/menus/menu_007_detail.webp | U8: src_01 | V8: VERIFIED | W8: 2026-10-19
A9: menu_008 | B9: ข้าวผัดกะเพราไก่ | C9: Stir-fried Basil Chicken with Rice | D9: cat_stir | E9: shop_tamsang | F9: 1 จาน | G9: 350 | H9: 50 | I9: 658 | J9: 30.1 | K9: 22.9 | L9: 82.6 | M9: 5 | N9: 3 | O9: 1500 | P9: =FALSE() | Q9: 2 | R9: ไก่|เผ็ด | S9: images/menus/menu_008_thumb.webp | T9: images/menus/menu_008_detail.webp | U9: src_01 | V9: VERIFIED | W9: 2026-10-19
A10: menu_009 | B10: ข้าวผัดหมู | C10: Pork Fried Rice | D10: cat_stir | E10: shop_tamsang | F10: 1 จาน | G10: 350 | H10: 50 | I10: 504 | J10: 20.1 | K10: 22.2 | L10: 55.6 | M10: 4 | N10: 2 | O10: 494 | P10: =FALSE() | Q10: 0 | R10: หมู|ข้าวผัด | S10: images/menus/menu_009_thumb.webp | T10: images/menus/menu_009_detail.webp | U10: src_01 | V10: VERIFIED | W10: 2026-10-19
A11: menu_010 | B11: ข้าวผัดอเมริกัน | C11: American Fried Rice | D11: cat_stir | E11: shop_tamsang | F11: 1 จาน | G11: 400 | H11: 70 | I11: 794 | J11: 37.7 | K11: 39.8 | L11: 66.8 | M11: 4.9 | N11: 4.8 | O11: 1567 | P11: =FALSE() | Q11: 0 | R11: ไส้กรอก|ไข่|พลังงานสูง | S11: images/menus/menu_010_thumb.webp | T11: images/menus/menu_010_detail.webp | U11: src_01 | V11: VERIFIED | W11: 2026-10-19
A12: menu_011 | B12: ข้าวผัดพริกแกงหมู | C12: Stir-fried Red Curry Paste with Pork and Rice | D12: cat_stir | E12: shop_tamsang | F12: 1 จาน | G12: 350 | H12: 55 | I12: 472 | J12: 25.2 | K12: 8.8 | L12: 68.8 | M12: 6.6 | N12: 8.2 | O12: 652 | P12: =FALSE() | Q12: 2 | R12: หมู|เผ็ด | S12: images/menus/menu_011_thumb.webp | T12: images/menus/menu_011_detail.webp | U12: src_01 | V12: VERIFIED | W12: 2026-10-19
A13: menu_012 | B13: ข้าวผัดกระเทียมหมู | C13: Garlic Pork with Rice | D13: cat_stir | E13: shop_tamsang | F13: 1 จาน | G13: 340 | H13: 50 | I13: 686 | J13: 38.8 | K13: 26.2 | L13: 73.3 | M13: 0 | N13: 0.3 | O13: 1078 | P13: =FALSE() | Q13: 0 | R13: หมู|กระเทียม | S13: images/menus/menu_012_thumb.webp | T13: images/menus/menu_012_detail.webp | U13: src_01 | V13: VERIFIED | W13: 2026-10-19
... A28: menu_027 | B28: สุกี้แห้งหมู | C28: Dry Suki with Pork | D28: cat_noodle | E28: shop_tamsang | F28: 1 จาน | G28: 350 | H28: 55 | I28: 413 | J28: 30.8 | K28: 19.7 | L28: 26.3 | M28: 0 | N28: 3.1 | O28: 1560 | P28: =FALSE() | Q28: 1 | R28: หมู|ผัก | S28: images/menus/menu_027_thumb.webp | T28: images/menus/menu_027_detail.webp | U28: src_01 | V28: VERIFIED | W28: 2026-10-19
A29: menu_028 | B29: ส้มตำไทย | C29: Thai Green Papaya Salad | D29: cat_isaan | E29: shop_isaan | F29: 1 จาน | G29: 200 | H29: 40 | I29: 210 | J29: 8.6 | K29: 5.3 | L29: 28.7 | M29: 14 | N29: 6.6 | O29: 1254 | P29: =TRUE() | Q29: 2 | R29: มังสวิรัติได้|ผัก|เผ็ด | S29: images/menus/menu_028_thumb.webp | T29: images/menus/menu_028_detail.webp | U29: src_01 | V29: VERIFIED | W29: 2026-10-19
A30: menu_029 | B30: ส้มตำปูปลาร้า | C30: Papaya Salad with Crab and Fermented Fish | D30: cat_isaan | E30: shop_isaan | F30: 1 จาน | G30: 220 | H30: 45 | I30: 62 | J30: 4 | K30: 0.7 | L30: 9.9 | M30: 9.9 | N30: 5 | O30: 1006 | P30: =FALSE() | Q30: 3 | R30: ปู|เผ็ด|โซเดียมสูง | S30: images/menus/menu_029_thumb.webp | T30: images/menus/menu_029_detail.webp | U30: src_01 | V30: VERIFIED | W30: 2026-10-19
A31: menu_030 | B31: ลาบหมู | C31: Spicy Minced Pork Salad | D31: cat_isaan | E31: shop_isaan | F31: 1 จาน | G31: 150 | H31: 50 | I31: 269 | J31: 29.6 | K31: 15.6 | L31: 2.3 | M31: 1.3 | N31: 0.6 | O31: 717 | P31: =FALSE() | Q31: 3 | R31: หมู|เผ็ด|โปรตีนสูง | S31: images/menus/menu_030_thumb.webp | T31: images/menus/menu_030_detail.webp | U31: src_01 | V31: VERIFIED | W31: 2026-10-19
A32: menu_031 | B32: ไก่ย่าง (หนึ่งในสี่ตัว) | C32: Grilled Chicken (Quarter) | D32: cat_isaan | E32: shop_isaan | F32: 1 ชิ้น | G32: 180 | H32: 60 | I32: 331 | J32: 53.4 | K32: 12.5 | L32: 0.8 | M32: 0.8 | N32: 1.3 | O32: 983 | P32: =FALSE() | Q32: 0 | R32: ไก่|โปรตีนสูง | S32: images/menus/menu_031_thumb.webp | T32: images/menus/menu_031_detail.webp | U32: src_01 | V32: VERIFIED | W32: 2026-10-19
A33: menu_032 | B33: คอหมูย่าง | C33: Grilled Pork Neck | D33: cat_isaan | E33: shop_isaan | F33: 1 จาน | G33: 150 | H33: 60 | I33: 426 | J33: 53.9 | K33: 21 | L33: 5.4 | M33: 2 | N33: 0 | O33: 225 | P33: =FALSE() | Q33: 0 | R33: หมู|ไขมันสูง | S33: images/menus/menu_032_thumb.webp | T33: images/menus/menu_032_detail.webp | U33: src_01 | V33: VERIFIED | W33: 2026-10-19
A34: menu_033 | B34: ข้าวเหนียว | C34: Sticky Rice | D34: cat_side | E34: shop_isaan | F34: 1 ห่อ | G34: 120 | H34: 10 | I34: 278 | J34: 5.4 | K34: 0.3 | L34: 63.5 | M34: 0 | N34: 0.4 | O34: 16 | P34: =TRUE() | Q34: 0 | R34: ข้าว|เครื่องเคียง | S34: images/menus/menu_033_thumb.webp | T34: images/menus/menu_033_detail.webp | U34: src_01 | V34: VERIFIED | W34: 2026-10-19
A35: menu_034 | B35: ต้มแซ่บกระดูกหมู | C35: Spicy Pork Rib Soup | D35: cat_isaan | E35: shop_isaan | F35: 1 ถ้วย | G35: 400 | H35: 60 | I35: 369 | J35: 34.4 | K35: 24.5 | L35: 2.3 | M35: 0.4 | N35: 0.6 | O35: 1043 | P35: =FALSE() | Q35: 3 | R35: หมู|เผ็ด|โซเดียมสูง | S35: images/menus/menu_034_thumb.webp | T35: images/menus/menu_034_detail.webp | U35: src_01 | V35: VERIFIED | W35: 2026-10-19
A36: menu_035 | B36: แกงเขียวหวานไก่ราดข้าว | C36: Green Curry Chicken with Rice | D36: cat_curry | E36: shop_curry | F36: 1 จาน | G36: 400 | H36: 50 | I36: 568 | J36: 26.4 | K36: 16 | L36: 76.7 | M36: 8 | N36: 4.8 | O36: 1500 | P36: =FALSE() | Q36: 2 | R36: ไก่|กะทิ | S36: images/menus/menu_035_thumb.webp | T36: images/menus/menu_035_detail.webp | U36: src_01 | V36: VERIFIED | W36: 2026-10-19
A37: menu_036 | B37: แกงจืดเต้าหู้หมูสับ | C37: Clear Soup with Tofu and Minced Pork | D37: cat_curry | E37: shop_curry | F37: 1 ถ้วย | G37: 350 | H37: 45 | I37: 180 | J37: 17.8 | K37: 10.5 | L37: 2.6 | M37: 0 | N37: 1.5 | O37: 747 | P37: =FALSE() | Q37: 0 | R37: หมู|เต้าหู้|พลังงานต่ำ | S37: images/menus/menu_036_thumb.webp | T37: images/menus/menu_036_detail.webp | U37: src_01 | V37: VERIFIED | W37: 2026-10-19
A38: menu_037 | B38: ต้มยำกุ้งน้ำข้น | C38: Creamy Tom Yum Goong | D38: cat_curry | E38: shop_tamsang | F38: 1 ถ้วย | G38: 350 | H38: 80 | I38: 154 | J38: 16.3 | K38: 5 | L38: 10 | M38: 7.3 | N38: 2.4 | O38: 1824 | P38: =FALSE() | Q38: 3 | R38: กุ้ง|เผ็ด|โซเดียมสูง | S38: images/menus/menu_037_thumb.webp | T38: images/menus/menu_037_detail.webp | U38: src_01 | V38: VERIFIED | W38: 2026-10-19
A39: menu_038 | B39: แกงส้มผักรวมกุ้ง | C39: Sour Curry with Mixed Vegetables and Shrimp | D39: cat_curry | E39: shop_curry | F39: 1 ถ้วย | G39: 350 | H39: 55 | I39: 108 | J39: 8.9 | K39: 0.6 | L39: 13.8 | M39: 12.9 | N39: 6.7 | O39: 1050 | P39: =FALSE() | Q39: 2 | R39: กุ้ง|ผัก | S39: images/menus/menu_038_thumb.webp | T39: images/menus/menu_038_detail.webp | U39: src_01 | V39: VERIFIED | W39: 2026-10-19
A40: menu_039 | B40: พะแนงหมูราดข้าว | C40: Panang Curry Pork with Rice | D40: cat_curry | E40: shop_curry | F40: 1 จาน | G40: 380 | H40: 55 | I40: 619 | J40: 27.3 | K40: 20.5 | L40: 80.2 | M40: 8.7 | N40: 3 | O40: 535 | P40: =FALSE() | Q40: 1 | R40: หมู|กะทิ | S40: images/menus/menu_039_thumb.webp | T40: images/menus/menu_039_detail.webp | U40: src_01 | V40: VERIFIED | W40: 2026-10-19
A41: menu_040 | B41: ผัดผักรวมมิตร | C41: Stir-fried Mixed Vegetables | D41: cat_curry | E41: shop_tamsang | F41: 1 จาน | G41: 200 | H41: 40 | I41: 138 | J41: 3.8 | K41: 10.4 | L41: 5.4 | M41: 0 | N41: 3.9 | O41: 349 | P41: =TRUE() | Q41: 0 | R41: ผัก|มังสวิรัติได้ | S41: images/menus/menu_040_thumb.webp | T41: images/menus/menu_040_detail.webp | U41: src_01 | V41: VERIFIED | W41: 2026-10-19
A42: menu_041 | B42: ผัดผักบุ้งไฟแดง | C42: Stir-fried Morning Glory | D42: cat_curry | E42: shop_tamsang | F42: 1 จาน | G42: 180 | H42: 40 | I42: 146 | J42: 3.7 | K42: 12.5 | L42: 2.1 | M42: 0 | N42: 4.6 | O42: 894 | P42: =TRUE() | Q42: 1 | R42: ผัก|มังสวิรัติได้ | S42: images/menus/menu_041_thumb.webp | T42: images/menus/menu_041_detail.webp | U42: src_01 | V42: VERIFIED | W42: 2026-10-19
A43: menu_042 | B43: ชาไทยเย็น | C43: Thai Iced Milk Tea | D43: cat_drink | E43: shop_drink | F43: 1 แก้ว | G43: 350 | H43: 30 | I43: 221 | J43: 4.4 | K43: 5 | L43: 40.3 | M43: 39.2 | N43: 0 | O43: 69 | P43: =TRUE() | Q43: 0 | R43: น้ำตาลสูง | S43: images/menus/menu_042_thumb.webp | T43: images/menus/menu_042_detail.webp | U43: src_01 | V43: VERIFIED | W43: 2026-10-19
A44: menu_043 | B44: กาแฟเย็น | C44: Thai Iced Coffee | D44: cat_drink | E44: shop_drink | F44: 1 แก้ว | G44: 350 | H44: 35 | I44: 204 | J44: 4.3 | K44: 4.6 | L44: 36.9 | M44: 36.3 | N44: 0 | O44: 67 | P44: =TRUE() | Q44: 0 | R44: น้ำตาลสูง|คาเฟอีน | S44: images/menus/menu_043_thumb.webp | T44: images/menus/menu_043_detail.webp | U44: src_01 | V44: VERIFIED | W44: 2026-10-19
A45: menu_044 | B45: โอเลี้ยง | C45: Thai Iced Black Coffee | D45: cat_drink | E45: shop_drink | F45: 1 แก้ว | G45: 350 | H45: 25 | I45: 138 | J45: 0.4 | K45: 0.1 | L45: 35 | M45: 34.9 | N45: 0 | O45: 7 | P45: =TRUE() | Q45: 0 | R45: น้ำตาลสูง|คาเฟอีน | S45: images/menus/menu_044_thumb.webp | T45: images/menus/menu_044_detail.webp | U45: src_01 | V45: VERIFIED | W45: 2026-10-19
A46: menu_045 | B46: น้ำเปล่า | C46: Drinking Water | D46: cat_drink | E46: shop_drink | F46: 1 ขวด | G46: 500 | H46: 10 | I46: 0 | J46: 0 | K46: 0 | L46: 0 | M46: 0 | N46: 0 | O46: 10 | P46: =TRUE() | Q46: 0 | R46: ไม่มีพลังงาน | S46: images/menus/menu_045_thumb.webp | T46: images/menus/menu_045_detail.webp | U46: src_01 | V46: VERIFIED | W46: 2026-10-19
A47: menu_046 | B47: นมถั่วเหลือง | C47: Soy Milk | D47: cat_drink | E47: shop_drink | F47: 1 ขวด | G47: 300 | H47: 20 | I47: 237 | J47: 8.7 | K47: 10 | L47: 26.9 | M47: 24.9 | N47: 2.1 | O47: 105 | P47: =TRUE() | Q47: 0 | R47: โปรตีนพืช|มังสวิรัติได้ | S47: images/menus/menu_046_thumb.webp | T47: images/menus/menu_046_detail.webp | U47: src_01 | V47: VERIFIED | W47: 2026-10-19
A48: menu_047 | B48: ข้าวเหนียวมะม่วง | C48: Mango with Sticky Rice | D48: cat_dessert | E48: shop_dessert | F48: 1 จาน | G48: 250 | H48: 60 | I48: 432 | J48: 4.6 | K48: 7.9 | L48: 84.3 | M48: 48 | N48: 3.5 | O48: 180 | P48: =TRUE() | Q48: 0 | R48: ของหวาน|น้ำตาลสูง | S48: images/menus/menu_047_thumb.webp | T48: images/menus/menu_047_detail.webp | U48: src_01 | V48: VERIFIED | W48: 2026-10-19
A49: menu_048 | B49: ผลไม้รวม (ฝรั่งและสับปะรด) | C49: Mixed Fruit (Guava and Pineapple) | D49: cat_dessert | E49: shop_dessert | F49: 1 กล่อง | G49: 200 | H49: 25 | I49: 84 | J49: 1.1 | K49: 0.1 | L49: 16.8 | M49: 16.8 | N49: 5.6 | O49: 11 | P49: =TRUE() | Q49: 0 | R49: ผลไม้|ใยอาหารสูง | S49: images/menus/menu_048_thumb.webp | T49: images/menus/menu_048_detail.webp | U49: src_01 | V49: VERIFIED | W49: 2026-10-19
A50: menu_049 | B50: ข้าวสวย | C50: Steamed Jasmine Rice | D50: cat_side | E50: shop_curry | F50: 1 จาน | G50: 160 | H50: 10 | I50: 218 | J50: 3.6 | K50: 0.4 | L50: 49.8 | M50: 0 | N50: 0.6 | O50: 32 | P50: =TRUE() | Q50: 0 | R50: ข้าว|เครื่องเคียง|มังสวิรัติได้ | S50: images/menus/menu_049_thumb.webp | T50: images/menus/menu_049_detail.webp | U50: src_01 | V50: VERIFIED | W50: 2026-10-19

Sheet articles
A1: article_id | B1: title_th | C1: title_en | D1: topic | E1: summary | F1: key_points | G1: source_ids | H1: related_nutrient | I1: reading_minutes | J1: cover_image | K1: status | L1: published_at
A2: article_01 | B2: พลังงานที่ร่างกายต้องการต่อวันคำนวณอย่างไร | C2: How to Calculate Your Daily Energy Needs | D2: basic | E2: อธิบายความหมายของ BMR และ TDEE พร้อมวิธีคำนวณด้วยสมการ Mifflin-St Jeor | F2: BMR คือพลังงานที่ร่างกายใช้ขณะพักเพื่อรักษาการทำงานพื้นฐาน เช่น การหายใจและการเต้นของหัวใจ | สมการ Mifflin-St Jeor สำหรับเพศชาย BMR = 10 × น้ำหนัก (กก.) + 6.25 × ส่วนสูง (ซม.) − 5 × อายุ (ปี) + 5 ส่วนเพศหญิงใช้ −161 แทน +5 | TDEE คือ BMR คูณตัวคูณระดับกิจกรรม ตั้งแต่ 1.2 สำหรับผู้ที่นั่งทำงานเป็นหลัก ถึง 1.9 สำหรับผู้ใช้แรงงานหนัก | ตัวเลขที่ได้เป็นค่าประมาณเพื่อใช้วางแผน ไม่ใช่ค่าที่วัดได้จริงของแต่ละบุคคล | G2: src_05|src_02 | H2: energy_kcal | I2: 4 | J2: images/articles/article_01_cover.webp | K2: PUBLISHED | L2: 2026-09-20
A3: article_02 | B3: อ่านฉลากโภชนาการอย่างไรให้เป็น | C3: How to Read a Nutrition Label | D3: basic | E3: อธิบายหน่วยบริโภค ร้อยละของปริมาณที่แนะนำต่อวัน และฉลากหวาน มัน เค็ม | F3: ค่าบนฉลากโภชนาการเป็นค่าต่อหนึ่งหน่วยบริโภค ไม่ใช่ต่อทั้งบรรจุภัณฑ์ จึงต้องดูจำนวนหน่วยบริโภคต่อภาชนะประกอบทุกครั้ง | ร้อยละของปริมาณที่แนะนำต่อวันบอกว่าหนึ่งหน่วยบริโภคให้สารอาหารคิดเป็นสัดส่วนเท่าใดของความต้องการทั้งวัน | ฉลากหวาน มัน เค็ม ด้านหน้าบรรจุภัณฑ์แสดงพลังงาน น้ำตาล ไขมัน และโซเดียมของทั้งบรรจุภัณฑ์ ช่วยให้เปรียบเทียบสินค้าได้เร็ว | อาหารปรุงสำเร็จหน้าร้านไม่มีฉลาก ระบบนี้จึงแสดงค่าต่อหนึ่งจานแทน | G3: src_06 | H3: general | I3: 4 | J3: images/articles/article_02_cover.webp | K3: PUBLISHED | L3: 2026-09-20
A4: article_03 | B4: โซเดียมแฝงในอาหารจานเดียวของไทย | C4: Hidden Sodium in Thai Single-dish Meals | D4: sodium | E4: เปรียบเทียบปริมาณโซเดียมของเมนูยอดนิยมกับเกณฑ์ไม่เกิน 2,000 มิลลิกรัมต่อวัน | F4: องค์การอนามัยโลกแนะนำให้ผู้ใหญ่บริโภคโซเดียมไม่เกิน 2,000 มิลลิกรัมต่อวัน ซึ่งเทียบเท่าเกลือประมาณ 5 กรัม | กรมอนามัยรายงานว่าคนไทยได้รับโซเดียมเฉลี่ย 3,636 มิลลิกรัมต่อวัน เกือบสองเท่าของเกณฑ์ | โซเดียมส่วนใหญ่มาจากน้ำปลา ซีอิ๊ว ซอสปรุงรส ผงปรุงรส และน้ำซุป ก๋วยเตี๋ยวน้ำหนึ่งชามจึงอาจให้โซเดียมเกือบทั้งวัน | วิธีลดที่ทำได้ทันทีคือไม่ซดน้ำซุปจนหมด ชิมก่อนเติมเครื่องปรุง และสลับเมนูรสจัดกับผัดผักหรือแกงจืด | G4: src_03|src_16|src_01 | H4: sodium_mg | I4: 5 | J4: images/articles/article_03_cover.webp | K4: PUBLISHED | L4: 2026-09-20
A5: article_04 | B5: น้ำตาลในเครื่องดื่ม หนึ่งแก้วเท่ากับกี่ช้อนชา | C5: Sugar in Beverages | D5: sugar | E5: แปลงปริมาณน้ำตาลในเครื่องดื่มเป็นจำนวนช้อนชาเพื่อให้เห็นภาพ | F5: องค์การอนามัยโลกแนะนำให้ได้รับน้ำตาลอิสระน้อยกว่าร้อยละ 10 ของพลังงานทั้งวัน สำหรับผู้ที่ต้องการ 2,000 กิโลแคลอรีคือไม่เกินประมาณ 50 กรัม และจะดียิ่งขึ้นหากต่ำกว่าร้อยละ 5 | น้ำตาล 1 ช้อนชามีประมาณ 4 กรัม ชาไทยเย็นหนึ่งแก้วในระบบมีน้ำตาลประมาณ 44 กรัม หรือราว 11 ช้อนชา | การสั่งหวานน้อย หรือเปลี่ยนเป็นน้ำเปล่าและนมถั่วเหลืองสูตรหวานน้อย ช่วยลดน้ำตาลได้มากโดยไม่ต้องเปลี่ยนมื้ออาหาร | G5: src_04|src_01 | H5: sugar_g | I5: 4 | J5: images/articles/article_04_cover.webp | K5: PUBLISHED | L5: 2026-09-20
A6: article_05 | B6: โปรตีนพอหรือยังใน 1 วัน | C6: Are You Getting Enough Protein | D6: protein | E6: อธิบายการประมาณความต้องการโปรตีนจากน้ำหนักตัวและแหล่งโปรตีนราคาประหยัด | F6: ระบบใช้เป้าหมายโปรตีนประมาณ 1.0 กรัมต่อน้ำหนักตัว 1 กิโลกรัมต่อวันสำหรับผู้ใหญ่ทั่วไป | ไข่ เต้าหู้ นม และเนื้อไก่เป็นแหล่งโปรตีนที่ราคาไม่สูงและหาได้ทั่วไป | อาหารจานเดียวบางเมนูให้พลังงานสูงแต่โปรตีนต่ำ การเพิ่มไข่ต้มหรือเลือกเนื้อสัตว์ไม่ติดมันช่วยให้ได้โปรตีนครบง่ายขึ้น | G6: src_02 | H6: protein_g | I6: 3 | J6: images/articles/article_05_cover.webp | K6: PUBLISHED | L6: 2026-09-20
A7: article_06 | B7: ใยอาหารกับปัญหาผักน้อยในอาหารจานเดียว | C7: Dietary Fiber and Low-vegetable Meals | D7: fiber | E7: อธิบายบทบาทของใยอาหารและวิธีเพิ่มผักในเมนูสั่งประจำ | F7: ผู้ใหญ่ควรได้รับใยอาหารประมาณ 25 กรัมต่อวัน | อาหารจานเดียวส่วนใหญ่ในระบบมีใยอาหารเพียง 2 ถึง 4 กรัมต่อจาน จึงได้ใยอาหารไม่ถึงเกณฑ์แม้จะกินครบสามมื้อ | เพิ่มใยอาหารได้ด้วยการเลือกผัดผัก ส้มตำ หรือแกงส้ม และกินผลไม้เป็นของว่างแทนขนมหวาน | G7: src_02|src_07 | H7: fiber_g | I7: 4 | J7: images/articles/article_06_cover.webp | K7: PUBLISHED | L7: 2026-09-20
A8: article_07 | B8: ธงโภชนาการและการจัดจานแบบ 2:1:1 | C8: Thai Nutrition Flag and the 2:1:1 Plate | D8: basic | E8: อธิบายสัดส่วนผัก ข้าว และเนื้อสัตว์ในหนึ่งจานตามแนวทางของไทย | F8: ธงโภชนาการแนะนำให้กินข้าวและแป้งเป็นหลัก เพิ่มผักและผลไม้ และกินน้ำมัน น้ำตาล และเกลือแต่น้อย | จานสุขภาพ 2:1:1 คือแบ่งจานเป็น 4 ส่วน เป็นผัก 2 ส่วน ข้าวหรือแป้ง 1 ส่วน และเนื้อสัตว์หรือโปรตีน 1 ส่วน | อาหารจานเดียวส่วนใหญ่มีข้าวมากและผักน้อยกว่าที่แนะนำ ควรสั่งผักเพิ่มหรือกินผลไม้ร่วมด้วย | G8: src_07 | H8: carb_g | I8: 3 | J8: images/articles/article_07_cover.webp | K8: PUBLISHED | L8: 2026-09-20
A9: article_08 | B9: สั่งอาหารตามสั่งอย่างไรให้พลังงานไม่เกิน | C9: Ordering Made-to-order Food Wisely | D9: practice | E9: รวมเทคนิคการสั่งอาหาร เช่น ขอน้ำมันน้อย ขอผักเพิ่ม และเลี่ยงของทอด | F9: การขอน้ำมันน้อยและลดเครื่องปรุงช่วยลดทั้งพลังงานและโซเดียมโดยไม่ต้องเปลี่ยนเมนู | เลือกเมนูผัดที่มีผักเป็นส่วนประกอบหลัก และหลีกเลี่ยงการสั่งของทอดควบคู่กับข้าวผัดในมื้อเดียวกัน | ในระบบ ข้าวผัดอเมริกันให้พลังงาน 850 กิโลแคลอรี ขณะที่ข้าวผัดกะเพราไก่ให้ 580 กิโลแคลอรีในราคาที่ถูกกว่า | G9: src_01|src_07 | H9: energy_kcal | I9: 4 | J9: images/articles/article_08_cover.webp | K9: PUBLISHED | L9: 2026-09-20
A10: article_09 | B10: ไขมันอิ่มตัว ไขมันไม่อิ่มตัว และไขมันทรานส์ | C10: Types of Dietary Fat | D10: fat | E10: อธิบายชนิดของไขมันและผลต่อสุขภาพในระยะยาว | F10: ไขมันไม่อิ่มตัวพบในน้ำมันพืชส่วนใหญ่ ถั่ว และปลา ส่วนไขมันอิ่มตัวพบมากในไขมันสัตว์ หนังสัตว์ และกะทิ | ประเทศไทยห้ามผลิต นำเข้า หรือจำหน่ายน้ำมันที่ผ่านกระบวนการเติมไฮโดรเจนบางส่วน ซึ่งเป็นแหล่งหลักของไขมันทรานส์ ตามประกาศกระทรวงสาธารณสุข (ฉบับที่ 388) พ.ศ. 2561 | ข้าวหมูกรอบ คอหมูย่าง และข้าวขาหมูในระบบมีไขมันตั้งแต่ 28 กรัมต่อจานขึ้นไป ควรสลับกับเมนูที่ใช้เนื้อสัตว์ไม่ติดมัน | G10: src_02|src_17 | H10: fat_g | I10: 5 | J10: images/articles/article_09_cover.webp | K10: PUBLISHED | L10: 2026-09-20
A11: article_10 | B11: กินมังสวิรัติหรือเจอย่างไรให้ได้โปรตีนครบ | C11: Getting Enough Protein on a Plant-based Diet | D11: protein | E11: แนะนำแหล่งโปรตีนจากพืชและการจับคู่อาหารให้ได้กรดอะมิโนครบ | F11: แหล่งโปรตีนจากพืชที่หาง่าย ได้แก่ เต้าหู้ ถั่วเหลือง นมถั่วเหลือง และถั่วชนิดต่าง ๆ | การกินโปรตีนจากพืชหลายชนิดร่วมกัน เช่น ข้าวกับถั่ว ช่วยให้ได้กรดอะมิโนจำเป็นครบถ้วนขึ้น | ในระบบสามารถกรองเฉพาะเมนูที่เหมาะกับมังสวิรัติ และควรตรวจสอบว่าโปรตีนรวมทั้งวันถึงเป้าหมาย | G11: src_02 | H11: protein_g | I11: 3 | J11: images/articles/article_10_cover.webp | K11: PUBLISHED | L11: 2026-09-20
A12: article_11 | B12: งบจำกัดแต่อยากกินให้ครบ 5 หมู่ | C12: Eating Well on a Limited Budget | D12: practice | E12: แนะนำการจัดมื้ออาหารให้ครบหมู่ภายใต้งบประมาณต่อวันที่กำหนด | F12: เมนูที่ราคาใกล้เคียงกันอาจให้สารอาหารต่างกันมาก การเปรียบเทียบค่าต่อจานช่วยให้เลือกได้คุ้มขึ้น | ฟังก์ชันวางแผนมื้ออาหารให้ผู้ใช้กำหนดงบประมาณต่อวัน แล้วเลือกชุดเมนูที่พลังงานใกล้เป้าหมายและโซเดียมไม่เกินเกณฑ์ | น้ำเปล่าและผลไม้ตามฤดูกาลเป็นทางเลือกราคาไม่สูงที่ช่วยลดน้ำตาลจากเครื่องดื่มหวาน | G12: src_07|src_08 | H12: general | I12: 4 | J12: images/articles/article_11_cover.webp | K12: PUBLISHED | L12: 2026-09-20
A13: article_12 | B13: ข้อจำกัดของการประมาณค่าโภชนาการอาหารปรุงสำเร็จ | C13: Limitations of Estimating Nutrition in Cooked Dishes | D13: basic | E13: อธิบายว่าเหตุใดค่าโภชนาการของอาหารปรุงสำเร็จจึงเป็นค่าประมาณและมีความแปรปรวน | F13: ค่าในระบบเป็นค่าต่อหนึ่งหน่วยบริโภคตามน้ำหนักที่ระบุ แต่ละร้านใช้ปริมาณและเครื่องปรุงไม่เท่ากัน ค่าจริงจึงอาจสูงหรือต่ำกว่า | ค่าอ้างอิงมาจากฐานข้อมูลองค์ประกอบอาหารไทย หรือคำนวณจากวัตถุดิบตามสูตรมาตรฐานเมื่อไม่มีเมนูนั้นในฐานข้อมูล | ระบบนี้เป็นเครื่องมือให้ความรู้ ไม่ใช่คำแนะนำทางการแพทย์ ผู้มีโรคประจำตัวควรปรึกษาแพทย์หรือนักกำหนดอาหาร | G13: src_01|src_02 | H13: general | I13: 3 | J13: images/articles/article_12_cover.webp | K13: PUBLISHED | L13: 2026-09-20

Sheet menu_images
A1: image_id | B1: entity_id | C1: image_type | D1: file_thumb | E1: file_detail | F1: source_id | G1: license | H1: status
A2: img_0001 | B2: menu_001 | C2: menu | D2: menu_001_thumb.webp | E2: menu_001_detail.webp | F2: src_10 | G2: CC BY 4.0 | H2: DONE
A3: img_0002 | B3: menu_002 | C3: menu | D3: menu_002_thumb.webp | E3: menu_002_detail.webp | F3: src_10 | G3: CC BY-SA 3.0 | H3: DONE
A4: img_0003 | B4: menu_003 | C4: menu | D4: menu_003_thumb.webp | E4: menu_003_detail.webp | F4: src_10 | G4: CC BY-SA 4.0 | H4: DONE
A5: img_0004 | B5: menu_004 | C5: menu | D5: menu_004_thumb.webp | E5: menu_004_detail.webp | F5: src_10 | G5: CC0 | H5: DONE
A6: img_0005 | B6: menu_005 | C6: menu | D6: menu_005_thumb.webp | E6: menu_005_detail.webp | F6: src_10 | G6: CC0 | H6: DONE
A7: img_0006 | B7: menu_006 | C7: menu | D7: menu_006_thumb.webp | E7: menu_006_detail.webp | F7: src_10 | G7: CC0 | H7: DONE
A8: img_0007 | B8: menu_007 | C8: menu | D8: menu_007_thumb.webp | E8: menu_007_detail.webp | F8: src_10 | G8: CC0 | H8: DONE
A9: img_0008 | B9: menu_008 | C9: menu | D9: menu_008_thumb.webp | E9: menu_008_detail.webp | F9: src_10 | G9: CC0 | H9: DONE
A10: img_0009 | B10: menu_009 | C10: menu | D10: menu_009_thumb.webp | E10: menu_009_detail.webp | F10: src_10 | G10: CC BY-SA 3.0 | H10: DONE
A11: img_0010 | B11: menu_010 | C11: menu | D11: menu_010_thumb.webp | E11: menu_010_detail.webp | F11: src_10 | G11: CC BY 2.0 | H11: DONE
A12: img_0011 | B12: menu_011 | C12: menu | D12: menu_011_thumb.webp | E12: menu_011_detail.webp | F12: src_10 | G12: CC BY 2.0 | H12: DONE
... A50: img_0049 | B50: menu_049 | C50: menu | D50: menu_049_thumb.webp | E50: menu_049_detail.webp | F50: src_10 | G50: CC0 | H50: DONE
A51: img_0050 | B51: article_01 | C51: article_cover | D51: article_01_cover.webp | F51: src_09 | G51: Own Work | H51: TODO
A52: img_0051 | B52: article_02 | C52: article_cover | D52: article_02_cover.webp | F52: src_09 | G52: Own Work | H52: TODO
A53: img_0052 | B53: article_03 | C53: article_cover | D53: article_03_cover.webp | F53: src_09 | G53: Own Work | H53: TODO
A54: img_0053 | B54: article_04 | C54: article_cover | D54: article_04_cover.webp | F54: src_09 | G54: Own Work | H54: TODO
A55: img_0054 | B55: article_05 | C55: article_cover | D55: article_05_cover.webp | F55: src_09 | G55: Own Work | H55: TODO
A56: img_0055 | B56: article_06 | C56: article_cover | D56: article_06_cover.webp | F56: src_09 | G56: Own Work | H56: TODO
A57: img_0056 | B57: article_07 | C57: article_cover | D57: article_07_cover.webp | F57: src_09 | G57: Own Work | H57: TODO
A58: img_0057 | B58: article_08 | C58: article_cover | D58: article_08_cover.webp | F58: src_09 | G58: Own Work | H58: TODO
A59: img_0058 | B59: article_09 | C59: article_cover | D59: article_09_cover.webp | F59: src_09 | G59: Own Work | H59: TODO
A60: img_0059 | B60: article_10 | C60: article_cover | D60: article_10_cover.webp | F60: src_09 | G60: Own Work | H60: TODO
A61: img_0060 | B61: article_11 | C61: article_cover | D61: article_11_cover.webp | F61: src_09 | G61: Own Work | H61: TODO
A62: img_0061 | B62: article_12 | C62: article_cover | D62: article_12_cover.webp | F62: src_09 | G62: Own Work | H62: TODO

Sheet sources
A1: source_id | B1: source_name | C1: source_type | D1: url_reference | E1: owner_license | F1: used_for
A2: src_01 | B2: ฐานข้อมูลองค์ประกอบอาหารไทยออนไลน์ (Thai Food Composition Database 2015) | C2: primary | D2: https://inmu.mahidol.ac.th/thaifcd/ | E2: สถาบันโภชนาการ มหาวิทยาลัยมหิดล | F2: menus (ค่าโภชนาการ ค่าต่อ 100 ก. × serving_g; รหัสอาหารรายเมนูใน menu_verification.csv)
A3: src_02 | B3: ปริมาณสารอาหารอ้างอิงที่ควรได้รับประจำวันสำหรับคนไทย พ.ศ. 2563 (Dietary Reference Intake for Thais 2020) | C3: secondary | D3: สำนักโภชนาการ กรมอนามัย https://nutrition2.anamai.moph.go.th/th/dri/176096 | E3: เอกสารราชการ | F3: nutrient_limits, articles
A4: src_03 | B4: WHO guideline: Sodium intake for adults and children | C4: secondary | D4: https://www.who.int/publications/i/item/9789241504836 | E4: World Health Organization | F4: เกณฑ์โซเดียมไม่เกิน 2,000 มก./วัน
A5: src_04 | B5: WHO guideline: Sugars intake for adults and children | C5: secondary | D5: https://www.who.int/publications/i/item/9789241549028 | E5: World Health Organization | F5: เกณฑ์น้ำตาลอิสระไม่เกินร้อยละ 10
A6: src_05 | B6: Mifflin, M. D. et al. (1990). A new predictive equation for resting energy expenditure | C6: secondary | D6: The American Journal of Clinical Nutrition, 51(2), 241-247 | E6: วารสารวิชาการ | F6: สูตรคำนวณ BMR
A7: src_06 | B7: ประกาศกระทรวงสาธารณสุข (ฉบับที่ 445) พ.ศ. 2566 เรื่อง ฉลากโภชนาการ | C7: secondary | D7: สำนักงานคณะกรรมการอาหารและยา https://food.fda.moph.go.th/local-economy/category/local-economy-nutrition-label | E7: เอกสารราชการ | F7: บทความเรื่องฉลากโภชนาการ
A8: src_07 | B8: คู่มือธงโภชนาการ และแนวทางจานสุขภาพ 2:1:1 ของกรมอนามัย | C8: secondary | D8: สำนักโภชนาการ กรมอนามัย https://nutrition2.anamai.moph.go.th/th/book/201525 | E8: เอกสารราชการ | F8: บทความเรื่องการจัดจาน
A9: src_08 | B9: สำรวจราคาและเมนูจากร้านอาหารตามสั่งและโรงอาหาร | C9: primary | D9: สำรวจโดยผู้จัดทำ | E9: Own Work | F9: menus.price_thb, serving_desc
A10: src_09 | B10: ภาพปกบทความ ไอคอน ภาพประกอบ และโลโก้ โดยผู้จัดทำ | C10: primary | D10: ผู้จัดทำ ร่วมกับเครื่องมือ AI | E10: Own Work + AI Assistance | F10: menu_images (ภาพปกบทความ), icons, branding
A11: src_10 | B11: ภาพเมนูจากคลังภาพที่มีสัญญาอนุญาตเปิด: Wikimedia Commons (48 เมนู) และ Flickr (1 เมนู, menu_027) | C11: asset | D11: https://commons.wikimedia.org และ https://www.flickr.com (ลิงก์รายไฟล์ใน images/menus/image_credits.csv) | E11: CC0 / Public domain / CC BY / CC BY-SA / CC BY-NC-SA (ระบุรายไฟล์) | F11: menu_images (ภาพเมนู 98 ไฟล์)
A12: src_11 | B12: Lucide Icons (ใช้เป็นแนวทางการออกแบบ ไม่ได้คัดลอกไฟล์) | C12: asset | D12: https://lucide.dev | E12: ISC License | F12: อ้างอิงรูปแบบไอคอนเส้น 24x24 stroke 2
... A21: src_20 | B21: Institute of Nutrition, Mahidol University. (2014). ASEAN Food Composition Database, Electronic version 1 (ค่าส่วนประกอบที่ไม่มีใน Thai FCD ออนไลน์: กะปิ หอมแดง มะม่วงดิบ ถั่วฝักยาว กุ้งแห้ง) | C21: secondary | D21: https://inmu.mahidol.ac.th/aseanfoods/doc/OnlineASEAN_FCD_V1_2014.pdf (ASEAN Food ID AAN31, AAN51 หน้า 28; AAE72 หน้า 12; AAD17 หน้า 10; AAG132 หน้า 21) | E21: สถาบันโภชนาการ มหาวิทยาลัยมหิดล (ASEANFOODS Regional Centre) | F21: ส่วนประกอบในการคำนวณค่าโภชนาการจากสูตรอาหาร menu_005 (menu_verification.csv)

Sheet menu_verification
A1: menu_id | B1: name_th | C1: verification_status | D1: match_type | E1: thaifcd_codes | F1: thaifcd_food_ids | G1: thaifcd_names | H1: grams_used | I1: serving_g | J1: energy_kcal_old | K1: energy_kcal_new | L1: protein_g_new | M1: fat_g_new | N1: carb_g_new | O1: fiber_g_new | P1: sugar_g_new | Q1: sodium_mg_old | R1: sodium_mg_new | S1: fields_retained_from_estimate | T1: other_source | U1: note | V1: checked_at
A2: menu_001 | B2: ข้าวมันไก่ | C2: VERIFIED | D2: exact | E2: T59 | F2: 1555 | G2: ข้าวมัน, ไก่ต้ม | H2: 350 | I2: 350 | J2: 596 | K2: 693 | L2: 23.6 | M2: 32.4 | N2: 74.4 | O2: 5.2 | P2: 3 | Q2: 1100 | R2: 1100 | S2: sugar_g|sodium_mg | V2: 2026-10-19
A3: menu_002 | B3: ข้าวหมูแดง | C3: VERIFIED | D3: exact | E3: T64 | F3: 1567 | G3: ข้าวหมูแดง | H3: 330 | I3: 330 | J3: 560 | K3: 508 | L3: 20.8 | M3: 13.8 | N3: 75 | O3: 0.7 | P3: 12 | Q3: 1200 | R3: 937 | S3: sugar_g | V3: 2026-10-19
A4: menu_003 | B4: ข้าวขาหมู | C4: VERIFIED | D4: exact | E4: T48 | F4: 1549 | G4: ข้าวขาหมู | H4: 380 | I4: 380 | J4: 680 | K4: 612 | L4: 27.3 | M4: 22.5 | N4: 73.5 | O4: 3.8 | P4: 8 | Q4: 1500 | R4: 1231 | S4: sugar_g | V4: 2026-10-19
A5: menu_004 | B5: ข้าวหน้าเป็ด | C5: VERIFIED | D5: exact | E5: T207 | F5: 1564 | G5: ข้าวหน้าเป็ดย่าง | H5: 350 | I5: 350 | J5: 620 | K5: 452 | L5: 18.2 | M5: 14.7 | N5: 58.5 | O5: 6.7 | P5: 6 | Q5: 1300 | R5: 1120 | S5: sugar_g | V5: 2026-10-19
A6: menu_005 | B6: ข้าวคลุกกะปิ | C6: VERIFIED | D6: recipe | E6: A11 + K41 + F86 + H4 + D335 | F6: 139 + 1364 + 965 + 1270 + 545 | G6: ข้าวเจ้า, สุก + น้ำมันถั่วเหลือง + หมู สันนอก ต้ม + ไข่ไก่ เจียว (เติมน้ำปลา) + พริกขี้หนู | H6: A11:188 + AAN31:12 + K41:6 + SUG:9 + F86:35 + SOY:3 + H4:20 + AAE72:20 + AAN51:10 + AAD17:10 + AAG132:5 + D335:2 | I6: 320 | J6: 610 | K6: 546 | L6: 25.5 | M6: 16.3 | N6: 73.8 | O6: 1.3 | P6: 9 | Q6: 1600 | R6: 1090 | T6: src_20 (AAN31, AAN51, AAE72, AAD17, AAG132); src_19 (SUG=FDC 169655, SOY=FDC 174277) | U6: ข้าวสวย 188 + กะปิ 12 + น้ำมัน 6 + หมูหวาน (หมูสันนอก 35 น้ำตาล 6 ซีอิ๊ว 3) + ไข่เจียวฝอย 20 (ใช้ค่าไข่เจียว) + มะม่วงดิบ 20 + หอมแดง 10 + ถั่วฝักยาว 10 + กุ้งแห้ง 5 + น้ำตาลคลุกข้าว 3 + พริก 2 ก.; พลังงานและคาร์โบไฮเดรตของกะปิ (AAN31) เป็นค่าคำนวณในวงเล็บของตาราง ASEAN; โซเดียมกุ้งแห้งใช้ AAG132 เพราะกุ้งแห้งเค็มของไทย (THG14) ไม่มีค่าโซเดียม ค่าจึงอาจต่ำกว่าจริงเล็กน้อย; น้ำตาลและใยอาหารนับเฉพาะส่วนประกอบที่มีค่ารายงาน | V6: 2026-10-19
A7: menu_006 | B7: ข้าวหมูกรอบ | C7: VERIFIED | D7: recipe | E7: A11 + F162 | F7: 139 + 982 | G7: ข้าวเจ้า, สุก + หมูกรอบ | H7: A11:200 + F162:80 + SUG:8 + SOY:7 + WAT:35 | I7: 330 | J7: 700 | K7: 708 | L7: 21 | M7: 38 | N7: 70.5 | O7: 0.1 | P7: 8 | Q7: 1250 | R7: 700 | T7: src_19 (SUG=FDC 169655, SOY=FDC 174277, WAT=FDC 174158);src_18 | U7: ข้าวสวย 200 + หมูกรอบ 80 + น้ำราด (ซีอิ๊ว 7 น้ำตาล 8 น้ำ 35) ก.; โซเดียมใช้ค่าต่อจานจาก src_18; น้ำตาลและใยอาหารนับเฉพาะส่วนประกอบที่มีค่ารายงาน | V7: 2026-10-19
A8: menu_007 | B8: ข้าวผัดกะเพราหมูสับไข่ดาว | C8: VERIFIED | D8: recipe | E8: A11 + F103 + H4 + K41 + D335 | F8: 139 + 972 + 1270 + 1364 + 545 | G8: ข้าวเจ้า, สุก + หมูสับ ทอด + ไข่ไก่ เจียว (เติมน้ำปลา) + น้ำมันถั่วเหลือง + พริกขี้หนู | H8: A11:208 + F103:90 + H4:50 + K41:8 + FISH:6 + OYS:8 + SOY:4 + SUG:3 + D335:3 | I8: 380 | J8: 680 | K8: 857 | L8: 40 | M8: 46 | N8: 70.5 | O8: 0.4 | P8: 3.2 | Q8: 1700 | R8: 1445 | T8: src_19 (FISH=FDC 174531, OYS=FDC 174529, SOY=FDC 174277, SUG=FDC 169655) | U8: ข้าวสวย 208 + หมูสับผัด 90 + ไข่ทอด 50 (ใช้ค่าไข่เจียว) + น้ำมัน 8 + เครื่องปรุง 21 ก.; ไม่รวมใบกะเพรา (Thai FCD ออนไลน์ไม่มีหมวดสมุนไพร); น้ำตาลและใยอาหารนับเฉพาะส่วนประกอบที่มีค่ารายงาน | V8: 2026-10-19
A9: menu_008 | B9: ข้าวผัดกะเพราไก่ | C9: VERIFIED | D9: exact | E9: T54 | F9: 1561 | G9: ข้าวราดไก่ผัดใบกะเพรา | H9: 350 | I9: 350 | J9: 580 | K9: 658 | L9: 30.1 | M9: 22.9 | N9: 82.6 | O9: 3 | P9: 5 | Q9: 1500 | R9: 1500 | S9: fiber_g|sugar_g|sodium_mg | V9: 2026-10-19
A10: menu_009 | B10: ข้าวผัดหมู | C10: VERIFIED | D10: exact | E10: T56 | F10: 1554 | G10: ข้าวผัดหมู | H10: 350 | I10: 350 | J10: 560 | K10: 504 | L10: 20.1 | M10: 22.2 | N10: 55.6 | O10: 2 | P10: 4 | Q10: 1200 | R10: 494 | S10: fiber_g|sugar_g | V10: 2026-10-19
A11: menu_010 | B11: ข้าวผัดอเมริกัน | C11: VERIFIED | D11: recipe | E11: T205 + F13 + F161 + H4 | F11: 1552 + 894 + 1011 + 1270 | G11: ข้าวผัดทั่วไป + ไก่ น่อง ทอด + ไส้กรอกหมู ทอด + ไข่ไก่ เจียว (เติมน้ำปลา) | H11: T205:250 + F13:60 + F161:30 + H4:50 + KET:10 | I11: 400 | J11: 850 | K11: 794 | L11: 37.7 | M11: 39.8 | N11: 66.8 | O11: 4.8 | P11: 4.9 | Q11: 1900 | R11: 1567 | T11: src_19 (KET=FDC 168556) | U11: ข้าวผัด (T205) 250 + ไก่ทอด 60 + ไส้กรอกทอด 30 + ไข่ทอด 50 + ซอสมะเขือเทศ 10 ก.; น้ำตาลและใยอาหารนับเฉพาะส่วนประกอบที่มีค่ารายงาน | V11: 2026-10-19
A12: menu_011 | B12: ข้าวผัดพริกแกงหมู | C12: VERIFIED | D12: recipe | E12: A11 + T224 | F12: 139 + 1503 | G12: ข้าวเจ้า, สุก + ผัดเผ็ดไก่ | H12: A11:200 + T224:150 | I12: 350 | J12: 620 | K12: 472 | L12: 25.2 | M12: 8.8 | N12: 68.8 | O12: 8.2 | P12: 6.6 | Q12: 1500 | R12: 652 | U12: ข้าวสวย 200 + ผัดเผ็ด (T224 ใช้ค่าผัดเผ็ดไก่แทนหมู) 150 ก.; น้ำตาลและใยอาหารนับเฉพาะส่วนประกอบที่มีค่ารายงาน | V12: 2026-10-19
A13: menu_012 | B13: ข้าวผัดกระเทียมหมู | C13: VERIFIED | D13: recipe | E13: A11 + F87 + K41 + D77 | F13: 139 + 966 + 1364 + 484 | G13: ข้าวเจ้า, สุก + หมู สันนอก ทอด + น้ำมันถั่วเหลือง + ผักกาดหอม ดิบ | H13: A11:200 + F87:110 + K41:10 + D77:20 | I13: 340 | J13: 590 | K13: 686 | L13: 38.8 | M13: 26.2 | N13: 73.3 | O13: 0.3 | P13: 0 | Q13: 1300 | R13: 1078 | U13: ข้าวสวย 200 + หมูสันนอกทอด 110 + น้ำมัน 10 + ผักเคียง 20 ก.; ค่าเทียบ T198 ข้าวกล้อง-หมูกระเทียม; น้ำตาลและใยอาหารนับเฉพาะส่วนประกอบที่มีค่ารายงาน | V13: 2026-10-19
A14: menu_013 | B14: ข้าวไข่เจียวหมูสับ | C14: VERIFIED | D14: recipe | E14: A11 + H4 + F103 | F14: 139 + 1270 + 972 | G14: ข้าวเจ้า, สุก + ไข่ไก่ เจียว (เติมน้ำปลา) + หมูสับ ทอด | H14: A11:190 + H4:90 + F103:20 | I14: 300 | J14: 620 | K14: 650 | L14: 23 | M14: 34.7 | N14: 61.3 | O14: 0 | P14: 0 | Q14: 1100 | R14: 614 | U14: ข้าวสวย 190 + ไข่เจียว 90 + หมูสับ 20 ก.; ค่าเทียบโซเดียม src_18 ข้าวไข่เจียว 362 มก.; น้ำตาลและใยอาหารนับเฉพาะส่วนประกอบที่มีค่ารายงาน | V14: 2026-10-19
A15: menu_014 | B15: ข้าวผัดคะน้าหมูกรอบ | C15: VERIFIED | D15: recipe | E15: A11 + D84 + F162 + K41 | F15: 139 + 491 + 982 + 1364 | G15: ข้าวเจ้า, สุก + ผักคะน้า ดิบ + หมูกรอบ + น้ำมันถั่วเหลือง | H15: A11:200 + D84:70 + F162:50 + K41:10 + OYS:10 + SOY:4 + SUG:3 + WAT:3 | I15: 350 | J15: 640 | K15: 647 | L15: 16.6 | M15: 34.2 | N15: 67.1 | O15: 2 | P15: 3 | Q15: 1550 | R15: 683 | T15: src_19 (OYS=FDC 174529, SOY=FDC 174277, SUG=FDC 169655, WAT=FDC 174158) | U15: ข้าวสวย 200 + คะน้า 70 + หมูกรอบ 50 + น้ำมัน 10 + เครื่องปรุง 20 ก.; น้ำตาลและใยอาหารนับเฉพาะส่วนประกอบที่มีค่ารายงาน | V15: 2026-10-19
A16: menu_015 | B16: ข้าวผัดผงกะหรี่ไก่ | C16: VERIFIED | D16: recipe | E16: A11 + F30 + H4 + D348 + D30 + K41 | F16: 139 + 908 + 1270 + 622 + 436 + 1364 | G16: ข้าวเจ้า, สุก + ไก่ อก รวมหนัง ต้ม + ไข่ไก่ เจียว (เติมน้ำปลา) + หอมหัวใหญ่ + ต้นหอม + น้ำมันถั่วเหลือง | H16: A11:200 + F30:60 + H4:30 + D348:30 + D30:5 + K41:10 + CUR:3 + OYS:6 + SOY:3 + SUG:3 | I16: 350 | J16: 600 | K16: 622 | L16: 27.1 | M16: 26.1 | N16: 70.1 | O16: 2.2 | P16: 3.1 | Q16: 1300 | R16: 597 | T16: src_19 (CUR=FDC 170924, OYS=FDC 174529, SOY=FDC 174277, SUG=FDC 169655) | U16: ข้าวสวย 200 + ไก่ 60 + ไข่ 30 + หอมใหญ่ 30 + ต้นหอม 5 + น้ำมัน 10 + ผงกะหรี่ 3 + เครื่องปรุง 12 ก.; น้ำตาลและใยอาหารนับเฉพาะส่วนประกอบที่มีค่ารายงาน | V16: 2026-10-19
A17: menu_016 | B17: ก๋วยเตี๋ยวหมูน้ำใส | C17: VERIFIED | D17: exact | E17: T127 | F17: 1594 | G17: เส้นใหญ่, หมู, น้ำ | H17: 450 | I17: 450 | J17: 350 | K17: 338 | L17: 31.9 | M17: 16.3 | N17: 12.4 | O17: 7.2 | P17: 4 | Q17: 1800 | R17: 1773 | S17: sugar_g | V17: 2026-10-19
A18: menu_017 | B18: ก๋วยเตี๋ยวต้มยำหมู | C18: VERIFIED | D18: recipe | E18: T127 + C106 + D335 | F18: 1594 + 345 + 545 | G18: เส้นใหญ่ หมู น้ำ + ถั่วลิสง คั่ว + พริกขี้หนู | H18: T127:422 + SUG:10 + C106:8 + FISH:7 + D335:3 | I18: 450 | J18: 480 | K18: 408 | L18: 32.5 | M18: 19.3 | N18: 23.1 | O18: 7.5 | P18: 10.2 | Q18: 2100 | R18: 2213 | T18: src_19 (SUG=FDC 169655, FISH=FDC 174531) | U18: ก๋วยเตี๋ยวเส้นใหญ่หมูน้ำ (T127) 422 + น้ำตาล 10 + ถั่วลิสง 8 + น้ำปลา 7 + พริก 3 ก.; น้ำตาลและใยอาหารนับเฉพาะส่วนประกอบที่มีค่ารายงาน | V18: 2026-10-19
A19: menu_018 | B19: เย็นตาโฟ | C19: VERIFIED | D19: exact | E19: T10 | F19: 1528 | G19: ก๋วยเตี๋ยวเส้นใหญ่, น้ำ, เย็นตาโฟ | H19: 450 | I19: 450 | J19: 420 | K19: 315 | L19: 13.7 | M19: 12 | N19: 37 | O19: 1.8 | P19: 16 | Q19: 2000 | R19: 1076 | S19: sugar_g | T19: src_18 | U19: ค่าโซเดียมเทียบ: ศิริราช 1,417 มก./ชาม | V19: 2026-10-19
A20: menu_019 | B20: ก๋วยเตี๋ยวเนื้อตุ๋น | C20: VERIFIED | D20: variant | E20: T112 | F20: 1583 | G20: เส้นหมี่, เนื้อเปื่อย, น้ำ | H20: 450 | I20: 450 | J20: 450 | K20: 356 | L20: 24.3 | M20: 12.2 | N20: 35.1 | O20: 3.6 | P20: 5 | Q20: 1900 | R20: 2538 | S20: sugar_g | U20: Thai FCD มีเฉพาะเส้นหมี่เนื้อเปื่อยน้ำ ใช้แทนก๋วยเตี๋ยวเนื้อตุ๋น | V20: 2026-10-19
A21: menu_020 | B21: บะหมี่เกี๊ยวหมูแดง | C21: VERIFIED | D21: variant | E21: T92 | F21: 1573 | G21: บะหมี่, หมูแดง, น้ำ | H21: 400 | I21: 400 | J21: 480 | K21: 408 | L21: 17.6 | M21: 34.4 | N21: 5.6 | O21: 3.6 | P21: 5.6 | Q21: 1700 | R21: 1352 | S21: sugar_g | T21: src_18 | U21: Thai FCD ไม่มีเกี๊ยว ใช้บะหมี่หมูแดงน้ำ; ค่าโซเดียมเทียบ: ศิริราช 1,480 มก./ชาม; น้ำตาลเดิม 6.0 ก. เกินคาร์โบไฮเดรตใหม่ ปรับเป็นเท่ากับคาร์โบไฮเดรต | V21: 2026-10-19
A22: menu_021 | B22: ผัดไทยกุ้งสด | C22: VERIFIED | D22: exact | E22: T9 | F22: 1525 | G22: ก๋วยเตี๋ยว, ผัดไทย | H22: 350 | I22: 350 | J22: 640 | K22: 598 | L22: 23.9 | M22: 22.2 | N22: 72.3 | O22: 7 | P22: 34.9 | Q22: 1400 | R22: 1558 | V22: 2026-10-19
A23: menu_022 | B23: ผัดซีอิ๊วหมู | C23: VERIFIED | D23: exact | E23: T11 | F23: 1529 | G23: ก๋วยเตี๋ยวเส้นใหญ่, ผัดซีอิ้ว, หมู | H23: 350 | I23: 350 | J23: 620 | K23: 774 | L23: 23.9 | M23: 43.1 | N23: 72.5 | O23: 3 | P23: 8 | Q23: 1600 | R23: 1337 | S23: fiber_g|sugar_g | T23: src_18 | U23: ค่าโซเดียมเทียบ: ศิริราช 1,352 มก./จาน | V23: 2026-10-19
A24: menu_023 | B24: ราดหน้าหมู | C24: VERIFIED | D24: exact | E24: T13 | F24: 1531 | G24: ก๋วยเตี๋ยวเส้นใหญ่, ราดหน้า, ไก่/หมู | H24: 400 | I24: 400 | J24: 560 | K24: 444 | L24: 11.8 | M24: 22.2 | N24: 49.2 | O24: 3 | P24: 10 | Q24: 1500 | R24: 1500 | S24: fiber_g|sugar_g|sodium_mg | V24: 2026-10-19
A25: menu_024 | B25: ก๋วยเตี๋ยวคั่วไก่ | C25: VERIFIED | D25: recipe | E25: A4 + F30 + H4 + K41 + D77 | F25: 164 + 908 + 1270 + 1364 + 484 | G25: ก๋วยเตี๋ยวเส้นใหญ่, สด + ไก่ อก รวมหนัง ต้ม + ไข่ไก่ เจียว (เติมน้ำปลา) + น้ำมันถั่วเหลือง + ผักกาดหอม ดิบ | H25: A4:200 + F30:60 + H4:40 + K41:15 + D77:25 + OYS:5 + SOY:3 + SUG:2 | I25: 350 | J25: 580 | K25: 720 | L25: 29.2 | M25: 36.9 | N25: 67.1 | O25: 1.8 | P25: 2 | Q25: 1450 | R25: 750 | T25: src_19 (OYS=FDC 174529, SOY=FDC 174277, SUG=FDC 169655) | U25: เส้นใหญ่ 200 + ไก่ 60 + ไข่ 40 + น้ำมัน 15 + ผักกาดหอม 25 + เครื่องปรุง 10 ก.; น้ำตาลและใยอาหารนับเฉพาะส่วนประกอบที่มีค่ารายงาน | V25: 2026-10-19
A26: menu_025 | B26: ขนมจีนน้ำยากะทิ | C26: VERIFIED | D26: exact | E26: T39 | F26: 1538 | G26: ขนมจีน, น้ำยา | H26: 400 | I26: 400 | J26: 520 | K26: 328 | L26: 10.8 | M26: 8.4 | N26: 51.7 | O26: 1.6 | P26: 6 | Q26: 1400 | R26: 1676 | S26: sugar_g | V26: 2026-10-19
A27: menu_026 | B27: สุกี้น้ำหมู | C27: VERIFIED | D27: recipe | E27: C124 + F86 + H18 + D323 + D94 + D30 | F27: 395 + 965 + 1271 + 479 + 507 + 436 | G27: วุ้นเส้น แช่ 15 นาที ลวก 3 นาที + หมู สันนอก ต้ม + ไข่ไก่ ต้ม 10 นาที + ผักกาดขาว สุก + ผักบุ้งจีน ดิบ + ต้นหอม | H27: C124:80 + F86:60 + H18:50 + D323:80 + D94:30 + D30:5 + WAT:95 | I27: 400 | J27: 380 | K27: 273 | L27: 27.7 | M27: 9 | N27: 18.5 | O27: 2.9 | P27: 0 | Q27: 1600 | R27: 1560 | T27: src_19 (WAT=FDC 174158);src_18 | U27: วุ้นเส้น 80 + หมู 60 + ไข่ 50 + ผัก 115 + น้ำซุป 95 ก.; โซเดียมใช้ค่าต่อชามสุกี้น้ำจาก src_18 (รวมน้ำจิ้ม); น้ำตาลและใยอาหารนับเฉพาะส่วนประกอบที่มีค่ารายงาน | V27: 2026-10-19
A28: menu_027 | B28: สุกี้แห้งหมู | C28: VERIFIED | D28: recipe | E28: C124 + F86 + H18 + D323 + D94 + K41 | F28: 395 + 965 + 1271 + 479 + 507 + 1364 | G28: วุ้นเส้น แช่ 15 นาที ลวก 3 นาที + หมู สันนอก ต้ม + ไข่ไก่ ต้ม 10 นาที + ผักกาดขาว สุก + ผักบุ้งจีน ดิบ + น้ำมันถั่วเหลือง | H28: C124:120 + F86:70 + H18:50 + D323:60 + D94:30 + K41:10 + WAT:10 | I28: 350 | J28: 520 | K28: 413 | L28: 30.8 | M28: 19.7 | N28: 26.3 | O28: 3.1 | P28: 0 | Q28: 1700 | R28: 1560 | T28: src_19 (WAT=FDC 174158);src_18 | U28: วุ้นเส้น 120 + หมู 70 + ไข่ 50 + ผัก 90 + น้ำมัน 10 ก.; โซเดียมใช้ค่าสุกี้น้ำจาก src_18 แทน (น้ำจิ้มปริมาณเท่ากัน); น้ำตาลและใยอาหารนับเฉพาะส่วนประกอบที่มีค่ารายงาน | V28: 2026-10-19
A29: menu_028 | B29: ส้มตำไทย | C29: VERIFIED | D29: exact | E29: T231 | F29: 1513 | G29: ส้มตำ, ไทย | H29: 200 | I29: 200 | J29: 135 | K29: 210 | L29: 8.6 | M29: 5.3 | N29: 28.7 | O29: 6.6 | P29: 14 | Q29: 900 | R29: 1254 | S29: sugar_g | V29: 2026-10-19
A30: menu_029 | B30: ส้มตำปูปลาร้า | C30: VERIFIED | D30: variant | E30: T103 | F30: 1515 | G30: ส้มตำ, อีสาน | H30: 220 | I30: 220 | J30: 150 | K30: 62 | L30: 4 | M30: 0.7 | N30: 9.9 | O30: 5 | P30: 9.9 | Q30: 1500 | R30: 1006 | S30: fiber_g|sugar_g | T30: src_18 | U30: ใช้ส้มตำอีสานแทนส้มตำปูปลาร้า; โซเดียมใช้ค่าต่อจานจากศิริราช (src_18) เพราะ Thai FCD ไม่รายงาน; น้ำตาลเดิม 10.0 ก. เกินคาร์โบไฮเดรตใหม่ ปรับเป็นเท่ากับคาร์โบไฮเดรต | V30: 2026-10-19
A31: menu_030 | B31: ลาบหมู | C31: VERIFIED | D31: recipe | E31: F102 + F77 + D348 + D30 + D335 | F31: 971 + 955 + 622 + 436 + 545 | G31: หมูสับ ต้ม + หมู ตับ ต้ม + หอมหัวใหญ่ + ต้นหอม + พริกขี้หนู | H31: F102:100 + F77:15 + FISH:8 + D348:12 + D30:10 + D335:2 + SUG:1 + WAT:2 | I31: 150 | J31: 230 | K31: 269 | L31: 29.6 | M31: 15.6 | N31: 2.3 | O31: 0.6 | P31: 1.3 | Q31: 1100 | R31: 717 | T31: src_19 (FISH=FDC 174531, SUG=FDC 169655, WAT=FDC 174158) | U31: หมูสับต้ม 100 + ตับ 15 + น้ำปลา 8 + หอม 12 + ต้นหอม 10 + พริก 2 + น้ำตาล 1 ก.; ไม่รวมข้าวคั่วและน้ำมะนาว; น้ำตาลและใยอาหารนับเฉพาะส่วนประกอบที่มีค่ารายงาน | V31: 2026-10-19
A32: menu_031 | B32: ไก่ย่าง (หนึ่งในสี่ตัว) | C32: VERIFIED | D32: exact | E32: F111 | F32: 900 | G32: ไก่, ย่าง | H32: 180 | I32: 180 | J32: 380 | K32: 331 | L32: 53.4 | M32: 12.5 | N32: 0.8 | O32: 1.3 | P32: 0.8 | Q32: 800 | R32: 983 | S32: sugar_g | U32: น้ำตาลเดิม 2.0 ก. เกินคาร์โบไฮเดรตใหม่ ปรับเป็นเท่ากับคาร์โบไฮเดรต | V32: 2026-10-19
A33: menu_032 | B33: คอหมูย่าง | C33: VERIFIED | D33: exact | E33: F97 | F33: 950 | G33: หมู, คอ, ย่าง | H33: 150 | I33: 150 | J33: 420 | K33: 426 | L33: 53.9 | M33: 21 | N33: 5.4 | O33: 0 | P33: 2 | Q33: 750 | R33: 225 | S33: sugar_g | V33: 2026-10-19
A34: menu_033 | B34: ข้าวเหนียว | C34: VERIFIED | D34: exact | E34: A23 | F34: 149 | G34: ข้าวเหนียว, นึ่ง | H34: 120 | I34: 120 | J34: 210 | K34: 278 | L34: 5.4 | M34: 0.3 | N34: 63.5 | O34: 0.4 | P34: 0 | Q34: 5 | R34: 16 | S34: sugar_g | V34: 2026-10-19
A35: menu_034 | B35: ต้มแซ่บกระดูกหมู | C35: VERIFIED | D35: recipe | E35: F73 + D348 + D335 + D30 | F35: 952 + 622 + 545 + 436 | G35: หมู ซี่โครง ต้ม + หอมหัวใหญ่ + พริกขี้หนู + ต้นหอม | H35: F73:130 + WAT:240 + FISH:12 + D348:10 + D335:3 + D30:5 | I35: 400 | J35: 320 | K35: 369 | L35: 34.4 | M35: 24.5 | N35: 2.3 | O35: 0.6 | P35: 0.4 | Q35: 1800 | R35: 1043 | T35: src_19 (WAT=FDC 174158, FISH=FDC 174531) | U35: ซี่โครงหมูต้ม 130 + น้ำ 240 + น้ำปลา 12 + หอม 10 + พริก 3 + ต้นหอม 5 ก.; น้ำตาลและใยอาหารนับเฉพาะส่วนประกอบที่มีค่ารายงาน | V35: 2026-10-19
A36: menu_035 | B36: แกงเขียวหวานไก่ราดข้าว | C36: VERIFIED | D36: exact | E36: T46 | F36: 1559 | G36: ข้าวราดแกงเขียวหวานไก่ | H36: 400 | I36: 400 | J36: 600 | K36: 568 | L36: 26.4 | M36: 16 | N36: 76.7 | O36: 4.8 | P36: 8 | Q36: 1500 | R36: 1500 | S36: sugar_g|sodium_mg | V36: 2026-10-19
A37: menu_036 | B37: แกงจืดเต้าหู้หมูสับ | C37: VERIFIED | D37: recipe | E37: H31 + F102 + D323 + D30 | F37: 1298 + 971 + 479 + 436 | G37: เต้าหู้ไข่ + หมูสับ ต้ม + ผักกาดขาว สุก + ต้นหอม | H37: H31:100 + F102:50 + D323:40 + WAT:150 + SOY:7 + D30:3 | I37: 350 | J37: 180 | K37: 180 | L37: 17.8 | M37: 10.5 | N37: 2.6 | O37: 1.5 | P37: 0 | Q37: 1200 | R37: 747 | T37: src_19 (WAT=FDC 174158, SOY=FDC 174277) | U37: เต้าหู้ไข่ 100 + หมูสับ 50 + ผักกาดขาว 40 + น้ำ 150 + ซีอิ๊ว 7 + ต้นหอม 3 ก.; น้ำตาลและใยอาหารนับเฉพาะส่วนประกอบที่มีค่ารายงาน | V37: 2026-10-19
A38: menu_037 | B38: ต้มยำกุ้งน้ำข้น | C38: VERIFIED | D38: variant | E38: T212 | F38: 1491 | G38: ต้มยำ, กุ้ง | H38: 350 | I38: 350 | J38: 300 | K38: 154 | L38: 16.3 | M38: 5 | N38: 10 | O38: 2.4 | P38: 7.3 | Q38: 1900 | R38: 1824 | U38: Thai FCD ไม่แยกต้มยำน้ำข้น ใช้ต้มยำกุ้ง | V38: 2026-10-19
A39: menu_038 | B39: แกงส้มผักรวมกุ้ง | C39: VERIFIED | D39: variant | E39: T191 | F39: 1471 | G39: แกงส้มผักรวม | H39: 350 | I39: 350 | J39: 220 | K39: 108 | L39: 8.9 | M39: 0.6 | N39: 13.8 | O39: 6.7 | P39: 12.9 | Q39: 1600 | R39: 1050 | T39: src_18 | U39: ใช้แกงส้มผักรวม (ไม่รวมกุ้ง); ค่าโซเดียมเทียบ: ศิริราช 1,130 มก./ชาม | V39: 2026-10-19
A40: menu_039 | B40: พะแนงหมูราดข้าว | C40: VERIFIED | D40: composite | E40: T188 + A11 | F40: 1467 + 139 | G40: แกงพะแนง, ไก่/หมู + ข้าวเจ้า, สุก | H40: 150 + 230 | I40: 380 | J40: 640 | K40: 619 | L40: 27.3 | M40: 20.5 | N40: 80.2 | O40: 3 | P40: 8.7 | Q40: 1450 | R40: 535 | S40: fiber_g | U40: แกงพะแนง 150 ก. + ข้าวสวย 230 ก. | V40: 2026-10-19
...

Sheet users
A1: user_id | B1: role | C1: display_name | D1: email | E1: sex | F1: birth_year | G1: height_cm | H1: weight_kg | I1: activity_id | J1: goal_id | K1: budget_per_day_thb | L1: created_at
A2: user_001 | B2: member | C2: กิตติพัฒน์ | D2: user001@nutriplan.test | E2: male | F2: 2543 | G2: 181 | H2: 67 | I2: act_active | J2: goal_maintain | K2: 100 | L2: 2026-09-06
A3: user_002 | B3: member | C3: ปวีณา | D3: user002@nutriplan.test | E3: female | F3: 2548 | G3: 149 | H3: 49.3 | I3: act_light | J3: goal_gain | K3: 180 | L3: 2026-09-06
A4: user_003 | B4: member | C4: ธนากร | D4: user003@nutriplan.test | E4: male | F4: 2542 | G4: 166 | H4: 74.4 | I4: act_light | J4: goal_gain | K4: 200 | L4: 2026-09-06
A5: user_004 | B5: member | C5: สุภัสสรา | D5: user004@nutriplan.test | E5: female | F5: 2542 | G5: 156 | H5: 58 | I5: act_active | J5: goal_maintain | K5: 150 | L5: 2026-09-06
A6: user_005 | B6: member | C6: ชยพล | D6: user005@nutriplan.test | E6: male | F6: 2548 | G6: 182 | H6: 84.4 | I6: act_light | J6: goal_maintain | K6: 180 | L6: 2026-09-06
A7: user_006 | B7: member | C7: พิมพ์ชนก | D7: user006@nutriplan.test | E7: female | F7: 2548 | G7: 162 | H7: 46.8 | I7: act_moderate | J7: goal_maintain | K7: 100 | L7: 2026-09-06
A8: user_007 | B8: member | C8: วรเมธ | D8: user007@nutriplan.test | E8: male | F8: 2544 | G8: 168 | H8: 56.6 | I8: act_sedentary | J8: goal_lose | K8: 120 | L8: 2026-09-06
A9: user_008 | B9: member | C9: ศิริกัญญา | D9: user008@nutriplan.test | E9: female | F9: 2548 | G9: 151 | H9: 65.7 | I9: act_light | J9: goal_maintain | K9: 150 | L9: 2026-09-06
A10: user_009 | B10: member | C10: ภูริภัทร | D10: user009@nutriplan.test | E10: male | F10: 2548 | G10: 165 | H10: 58.8 | I10: act_active | J10: goal_lose | K10: 150 | L10: 2026-09-06
A11: user_010 | B11: member | C11: กมลชนก | D11: user010@nutriplan.test | E11: female | F11: 2549 | G11: 150 | H11: 60.9 | I11: act_moderate | J11: goal_lose | K11: 150 | L11: 2026-09-06
A12: user_011 | B12: member | C12: อนุชา | D12: user011@nutriplan.test | E12: male | F12: 2547 | G12: 179 | H12: 59.3 | I12: act_active | J12: goal_lose | K12: 200 | L12: 2026-09-06
A13: user_012 | B13: member | C13: ณัฐริกา | D13: user012@nutriplan.test | E13: female | F13: 2547 | G13: 153 | H13: 58.6 | I13: act_light | J13: goal_gain | K13: 150 | L13: 2026-09-06
... A26: user_025 | B26: admin | C26: ธนพร | D26: user025@nutriplan.test | E26: female | F26: 2545 | G26: 149 | H26: 57.2 | I26: act_sedentary | J26: goal_gain | K26: 180 | L26: 2026-09-06

Sheet user_targets
A1: user_id | B1: age_year | C1: bmr_kcal | D1: tdee_kcal | E1: target_kcal | F1: target_protein_g | G1: limit_sodium_mg | H1: limit_sugar_g | I1: target_fiber_g | J1: calculated_at | L1: หมายเหตุ
A2: =users!A2 | B2: =2569-users!F2 | C2: =ROUND(10*users!H2+6.25*users!G2-5*B2+IF(users!E2="male",5,-161),0) | D2: =ROUND(C2*INDEX(activity_levels!$C$2:$C$6,MATCH(users!I2,activity_levels!$A$2:$A$6,0)),0) | E2: =D2+INDEX(health_goals!$C$2:$C$4,MATCH(users!J2,health_goals!$A$2:$A$4,0)) | F2: =ROUND(users!H2*1,0) | G2: =INDEX(nutrient_limits!$F$2:$F$8,MATCH("sodium_mg",nutrient_limits!$A$2:$A$8,0)) | H2: =INDEX(nutrient_limits!$F$2:$F$8,MATCH("sugar_g",nutrient_limits!$A$2:$A$8,0)) | I2: =INDEX(nutrient_limits!$F$2:$F$8,MATCH("fiber_g",nutrient_limits!$A$2:$A$8,0)) | J2: 2026-09-20 | L2: ทุกคอลัมน์ยกเว้น calculated_at เป็นสูตร: age = 2569 − birth_year (ปี พ.ศ. ของวันที่คำนวณ), BMR ตามสมการ Mifflin-St Jeor (src_05), TDEE = BMR × pal_factor, target_kcal = TDEE + kcal_adjust, โปรตีน = น้ำหนัก × 1.0 ก./กก. (src_02), เพดานโซเดียม/น้ำตาล/ใยอาหารดึงจากชีต nutrient_limits
A3: =users!A3 | B3: =2569-users!F3 | C3: =ROUND(10*users!H3+6.25*users!G3-5*B3+IF(users!E3="male",5,-161),0) | D3: =ROUND(C3*INDEX(activity_levels!$C$2:$C$6,MATCH(users!I3,activity_levels!$A$2:$A$6,0)),0) | E3: =D3+INDEX(health_goals!$C$2:$C$4,MATCH(users!J3,health_goals!$A$2:$A$4,0)) | F3: =ROUND(users!H3*1,0) | G3: =INDEX(nutrient_limits!$F$2:$F$8,MATCH("sodium_mg",nutrient_limits!$A$2:$A$8,0)) | H3: =INDEX(nutrient_limits!$F$2:$F$8,MATCH("sugar_g",nutrient_limits!$A$2:$A$8,0)) | I3: =INDEX(nutrient_limits!$F$2:$F$8,MATCH("fiber_g",nutrient_limits!$A$2:$A$8,0)) | J3: 2026-09-20
A4: =users!A4 | B4: =2569-users!F4 | C4: =ROUND(10*users!H4+6.25*users!G4-5*B4+IF(users!E4="male",5,-161),0) | D4: =ROUND(C4*INDEX(activity_levels!$C$2:$C$6,MATCH(users!I4,activity_levels!$A$2:$A$6,0)),0) | E4: =D4+INDEX(health_goals!$C$2:$C$4,MATCH(users!J4,health_goals!$A$2:$A$4,0)) | F4: =ROUND(users!H4*1,0) | G4: =INDEX(nutrient_limits!$F$2:$F$8,MATCH("sodium_mg",nutrient_limits!$A$2:$A$8,0)) | H4: =INDEX(nutrient_limits!$F$2:$F$8,MATCH("sugar_g",nutrient_limits!$A$2:$A$8,0)) | I4: =INDEX(nutrient_limits!$F$2:$F$8,MATCH("fiber_g",nutrient_limits!$A$2:$A$8,0)) | J4: 2026-09-20
A5: =users!A5 | B5: =2569-users!F5 | C5: =ROUND(10*users!H5+6.25*users!G5-5*B5+IF(users!E5="male",5,-161),0) | D5: =ROUND(C5*INDEX(activity_levels!$C$2:$C$6,MATCH(users!I5,activity_levels!$A$2:$A$6,0)),0) | E5: =D5+INDEX(health_goals!$C$2:$C$4,MATCH(users!J5,health_goals!$A$2:$A$4,0)) | F5: =ROUND(users!H5*1,0) | G5: =INDEX(nutrient_limits!$F$2:$F$8,MATCH("sodium_mg",nutrient_limits!$A$2:$A$8,0)) | H5: =INDEX(nutrient_limits!$F$2:$F$8,MATCH("sugar_g",nutrient_limits!$A$2:$A$8,0)) | I5: =INDEX(nutrient_limits!$F$2:$F$8,MATCH("fiber_g",nutrient_limits!$A$2:$A$8,0)) | J5: 2026-09-20
A6: =users!A6 | B6: =2569-users!F6 | C6: =ROUND(10*users!H6+6.25*users!G6-5*B6+IF(users!E6="male",5,-161),0) | D6: =ROUND(C6*INDEX(activity_levels!$C$2:$C$6,MATCH(users!I6,activity_levels!$A$2:$A$6,0)),0) | E6: =D6+INDEX(health_goals!$C$2:$C$4,MATCH(users!J6,health_goals!$A$2:$A$4,0)) | F6: =ROUND(users!H6*1,0) | G6: =INDEX(nutrient_limits!$F$2:$F$8,MATCH("sodium_mg",nutrient_limits!$A$2:$A$8,0)) | H6: =INDEX(nutrient_limits!$F$2:$F$8,MATCH("sugar_g",nutrient_limits!$A$2:$A$8,0)) | I6: =INDEX(nutrient_limits!$F$2:$F$8,MATCH("fiber_g",nutrient_limits!$A$2:$A$8,0)) | J6: 2026-09-20
